Workbook
Name NativeTimeline_Date_created: #N/A
Name Slicer_File_extension: #N/A
Name Slicer_Folder: #N/A

Sheet PivotTables
G1: File extension2 | H1: (All)
A3: File extension2 | B3: File extension | C3: Sum of Size | D3: Sum of Size | E3: Sum of Size KB 1024 | G3: File extension | H3: Years | I3: Sum of Size | J3: # | K3: Sum of Size | M3: Years | N3: Months | O3: Date created | P3: Sum of Size
A4: Starting with M | B4: .m4b | C4: 289489212 | D4: 289489212 | E4: 282704.31 | G4: .m4b | H4: 2010 | I4: 289489212 | J4: 1-100 | K4: 481004932 | M4: 2006 | N4: Jun | O4: 13-Jun | P4: 3161134
B5: .mp3 | C5: 1576168768 | D5: 1576168768 | E5: 1539227.3 | G5: .m4b Total | I5: 289489212 | J5: 101-200 | K5: 41315518 | N5: Jun Total | P5: 3161134
A6: Starting with M Total | C6: 1865657980 | D6: 1865657980 | E6: 1821931.6 | G6: .mp3 | H6: 2008 | I6: 165547958 | J6: 201-300 | K6: 900693138 | N6: Dec | O6: 30-Dec | P6: 155254282
A7: Starting with W | B7: .wma | C7: 4289308854 | D7: 4289308854 | E7: 4188778.2 | H7: 2010 | I7: 1021256966 | J7: 301-400 | K7: 313510660 | N7: Dec Total | P7: 155254282
B8: .wmaa | C8: 12658286 | D8: 12658286 | E8: 12361.607 | H8: 2011 | I8: 171536053 | J8: 401-500 | K8: 830762034 | M8: 2006 Total | P8: 158415416
A9: Starting with W Total | C9: 4301967140 | D9: 4301967140 | E9: 4201139.8 | H9: 2012 | I9: 95718176 | J9: 501-600 | K9: 316996338 | M9: 2007 | N9: Jun | O9: 24-Jun | P9: 277624050
A10: Grand Total | C10: 6167625120 | D10: 6167625120 | E10: 6023071.4 | H10: 2013 | I10: 122109615 | J10: 601-700 | K10: 645822686 | O10: 25-Jun | P10: 710663450
G11: .mp3 Total | I11: 1576168768 | J11: 701-800 | K11: 385840516 | O11: 27-Jun | P11: 456850184
G12: .wma | H12: 2006 | I12: 158415416 | J12: 801-900 | K12: 185109052 | O12: 28-Jun | P12: 375120836
H13: 2007 | I13: 2821396994 | J13: 901-1000 | K13: 789432258 | O13: 29-Jun | P13: 373715806
H14: 2008 | I14: 52758350 | J14: 1001-1100 | K14: 561522068 | N14: Jun Total | P14: 2193974326
H15: 2009 | I15: 190515060 | J15: 1101-1200 | K15: 610566414 | N15: Jul | O15: 2-Jul | P15: 80403062
H16: 2010 | I16: 717178956 | J16: 1201-1300 | K16: 105049506 | O16: 7-Jul | P16: 297481354
H17: 2014 | I17: 349044078 | J17: Grand Total | K17: 6167625120 | O17: 8-Jul | P17: 98226756
G18: .wma Total | I18: 4289308854 | N18: Jul Total | P18: 476111172
G19: .wmaa | H19: 2007 | I19: 12658286 | N19: Nov | O19: 5-Nov | P19: 163969782
G20: .wmaa Total | I20: 12658286 | N20: Nov Total | P20: 163969782
G21: Grand Total | I21: 6167625120 | M21: 2007 Total | P21: 2834055280
M22: 2008 | N22: Jul | O22: 30-Jul | P22: 165547958
N23: Jul Total | P23: 165547958
N24: Oct | O24: 21-Oct | P24: 52758350
N25: Oct Total | P25: 52758350
M26: 2008 Total | P26: 218306308
M27: 2009 | N27: Aug | O27: 24-Aug | P27: 190515060
N28: Aug Total | P28: 190515060
M29: 2009 Total | P29: 190515060
M30: 2010 | N30: Mar | O30: 6-Mar | P30: 1021256966
N31: Mar Total | P31: 1021256966
N32: May | O32: 16-May | P32: 289489212
O33: 21-May | P33: 717178956
N34: May Total | P34: 1006668168
M35: 2010 Total | P35: 2027925134
M36: 2011 | N36: Jul | O36: 17-Jul | P36: 35965571
O37: 26-Jul | P37: 57853963
N38: Jul Total | P38: 93819534
N39: Nov | O39: 22-Nov | P39: 27743275
N40: Nov Total | P40: 27743275
N41: Dec | O41: 4-Dec | P41: 28224860
...

Sheet CDs
A1: CD Catalogue | D1: 05 Requiem.- tuba mirum.wma | F1: =VLOOKUP($D1,$B4:$D861,3,FALSE) -> \10 Romantic works\
A3: # | B3: Filename | C3: File extension | D3: Folder | E3: Size | F3: Date created | G3: Title | H3: Authors | I3: Category | J3: Is Medium File OR .mp3
A4: 17 | B4: 02 Symphony 3 in F Mayor 1est. Mov.wma | C4: .wma | D4: \10 Romantic works\ | E4: 7217934 | F4: 39261.907 | G4: Symphony 3 in F Mayor 1est. Mov | H4: Berlin Symphony Orch, | I4: =VLOOKUP(D4,Categories!$A$1:$D$53,MATCH(I$3,Categories!$A$1:$D$1,0),FALSE) -> Sampler | J4: =IF(OR(AND(E4>1000000, E4<5000000), C4 = ".mp3"),"Yes","No") -> No | K4: {=_xlfn.IFS(C4=".mp3","Yes",AND(E4>1000000,E4<5000000),"Yes",TRUE,"No")} -> No | L4: {=_xlfn.SWITCH(C4,".wma","This is a WMA file!",".mp3","MP3 are great!","This is a different type of file")} -> This is a WMA file!
A5: 18 | B5: 03 Rastlose Liebe.wma | C5: .wma | D5: \10 Romantic works\ | E5: 1983338 | F5: 39261.907 | G5: Rastlose Liebe | H5: Blackwitz tenor, Jansen piano | I5: =VLOOKUP(D5,Categories!$A$1:$D$53,MATCH(I$3,Categories!$A$1:$D$1,0),FALSE) -> Sampler | J5: =IF(OR(AND(E5>1000000, E5<5000000), C5 = ".mp3"),"Yes","No") -> Yes | K5: {=_xlfn.IFS(C5=".mp3","Yes",AND(E5>1000000,E5<5000000),"Yes",TRUE,"No")} -> Yes | L5: {=_xlfn.SWITCH(C5,".wma","This is a WMA file!",".mp3","MP3 are great!","This is a different type of file")} -> This is a WMA file!
A6: 19 | B6: 05 Requiem.- tuba mirum.wma | C6: .wma | D6: \10 Romantic works\ | E6: 8336412 | F6: 39261.907 | G6: Requiem.- tuba mirum | H6: Boston Symph. Orch. | I6: =VLOOKUP(D6,Categories!$A$1:$D$53,MATCH(I$3,Categories!$A$1:$D$1,0),FALSE) -> Sampler | J6: =IF(OR(AND(E6>1000000, E6<5000000), C6 = ".mp3"),"Yes","No") -> No | K6: {=_xlfn.IFS(C6=".mp3","Yes",AND(E6>1000000,E6<5000000),"Yes",TRUE,"No")} -> No | L6: {=_xlfn.SWITCH(C6,".wma","This is a WMA file!",".mp3","MP3 are great!","This is a different type of file")} -> This is a WMA file!
A7: 20 | B7: 06 Annees de pelerinage.wma | C7: .wma | D7: \10 Romantic works\ | E7: 12040860 | F7: 39261.907 | G7: Annees de pelerinage | H7: Jando piano | I7: =VLOOKUP(D7,Categories!$A$1:$D$53,MATCH(I$3,Categories!$A$1:$D$1,0),FALSE) -> Sampler | J7: =IF(OR(AND(E7>1000000, E7<5000000), C7 = ".mp3"),"Yes","No") -> No | K7: {=_xlfn.IFS(C7=".mp3","Yes",AND(E7>1000000,E7<5000000),"Yes",TRUE,"No")} -> No | L7: {=_xlfn.SWITCH(C7,".wma","This is a WMA file!",".mp3","MP3 are great!","This is a different type of file")} -> This is a WMA file!
A8: 21 | B8: 07 Romeo and Juliet.wma | C8: .wma | D8: \10 Romantic works\ | E8: 4748272 | F8: 39261.907 | G8: Romeo and Juliet | H8: Leipzig Gewanchaus Orch. | I8: =VLOOKUP(D8,Categories!$A$1:$D$53,MATCH(I$3,Categories!$A$1:$D$1,0),FALSE) -> Sampler | J8: =IF(OR(AND(E8>1000000, E8<5000000), C8 = ".mp3"),"Yes","No") -> Yes | K8: {=_xlfn.IFS(C8=".mp3","Yes",AND(E8>1000000,E8<5000000),"Yes",TRUE,"No")} -> Yes | L8: {=_xlfn.SWITCH(C8,".wma","This is a WMA file!",".mp3","MP3 are great!","This is a different type of file")} -> This is a WMA file!
A9: 22 | B9: 08 Symphony No. 1 in B flat major.wma | C9: .wma | D9: \10 Romantic works\ | E9: 6108364 | F9: 39261.907 | G9: Symphony No. 1 in B flat major | H9: Hanover Band | I9: =VLOOKUP(D9,Categories!$A$1:$D$53,MATCH(I$3,Categories!$A$1:$D$1,0),FALSE) -> Sampler | J9: =IF(OR(AND(E9>1000000, E9<5000000), C9 = ".mp3"),"Yes","No") -> No | K9: {=_xlfn.IFS(C9=".mp3","Yes",AND(E9>1000000,E9<5000000),"Yes",TRUE,"No")} -> No | L9: {=_xlfn.SWITCH(C9,".wma","This is a WMA file!",".mp3","MP3 are great!","This is a different type of file")} -> This is a WMA file!
A10: 23 | B10: 09 Tango.wma | C10: .wma | D10: \10 Romantic works\ | E10: 4256086 | F10: 39261.907 | G10: Tango | H10: Cherskasky piano | I10: =VLOOKUP(D10,Categories!$A$1:$D$53,MATCH(I$3,Categories!$A$1:$D$1,0),FALSE) -> Sampler | J10: =IF(OR(AND(E10>1000000, E10<5000000), C10 = ".mp3"),"Yes","No") -> Yes | K10: {=_xlfn.IFS(C10=".mp3","Yes",AND(E10>1000000,E10<5000000),"Yes",TRUE,"No")} -> Yes | L10: {=_xlfn.SWITCH(C10,".wma","This is a WMA file!",".mp3","MP3 are great!","This is a different type of file")} -> This is a WMA file!
A11: 24 | B11: 10 Tristan e Islode.wma | C11: .wmaa | D11: \10 Romantic works\ | E11: 12658286 | F11: 39261.907 | G11: Tristan e Islode | H11: Welsh National Opera | I11: =VLOOKUP(D11,Categories!$A$1:$D$53,MATCH(I$3,Categories!$A$1:$D$1,0),FALSE) -> Sampler | J11: =IF(OR(AND(E11>1000000, E11<5000000), C11 = ".mp3"),"Yes","No") -> No | K11: {=_xlfn.IFS(C11=".mp3","Yes",AND(E11>1000000,E11<5000000),"Yes",TRUE,"No")} -> No | L11: {=_xlfn.SWITCH(C11,".wma","This is a WMA file!",".mp3","MP3 are great!","This is a different type of file")} -> This is a different type of file
A12: 25 | B12: 11 La taberna del Puerto.wma | C12: .wma | D12: \10 Romantic works\ | E12: 3737166 | F12: 39261.907 | G12: La taberna del Puerto | H12: Carreras tenor English Chamber | I12: =VLOOKUP(D12,Categories!$A$1:$D$53,MATCH(I$3,Categories!$A$1:$D$1,0),FALSE) -> Sampler | J12: =IF(OR(AND(E12>1000000, E12<5000000), C12 = ".mp3"),"Yes","No") -> Yes | K12: {=_xlfn.IFS(C12=".mp3","Yes",AND(E12>1000000,E12<5000000),"Yes",TRUE,"No")} -> Yes | L12: {=_xlfn.SWITCH(C12,".wma","This is a WMA file!",".mp3","MP3 are great!","This is a different type of file")} -> This is a WMA file!
A13: 26 | B13: 12 Cello concerto.wma | C13: .wma | D13: \10 Romantic works\ | E13: 3057104 | F13: 39261.907 | G13: Cello concerto | H13: Ma cello Baltimore Symphony Orch. | I13: =VLOOKUP(D13,Categories!$A$1:$D$53,MATCH(I$3,Categories!$A$1:$D$1,0),FALSE) -> Sampler | J13: =IF(OR(AND(E13>1000000, E13<5000000), C13 = ".mp3"),"Yes","No") -> Yes | K13: {=_xlfn.IFS(C13=".mp3","Yes",AND(E13>1000000,E13<5000000),"Yes",TRUE,"No")} -> Yes | L13: {=_xlfn.SWITCH(C13,".wma","This is a WMA file!",".mp3","MP3 are great!","This is a different type of file")} -> This is a WMA file!
A14: 27 | B14: 13 Dream Children.wma | C14: .wma | D14: \10 Romantic works\ | E14: 5115114 | F14: 39261.907 | G14: Dream Children | H14: BBC Symphopny Orch. | I14: =VLOOKUP(D14,Categories!$A$1:$D$53,MATCH(I$3,Categories!$A$1:$D$1,0),FALSE) -> Sampler | J14: =IF(OR(AND(E14>1000000, E14<5000000), C14 = ".mp3"),"Yes","No") -> No | K14: {=_xlfn.IFS(C14=".mp3","Yes",AND(E14>1000000,E14<5000000),"Yes",TRUE,"No")} -> No | L14: {=_xlfn.SWITCH(C14,".wma","This is a WMA file!",".mp3","MP3 are great!","This is a different type of file")} -> This is a WMA file!
A15: 28 | B15: 14 Violin concerto In F major Op.7.wma | C15: .wma | D15: \10 Romantic works\ | E15: 5517848 | F15: 39261.907 | G15: Violin concerto In F major Op.7 | H15: Standadge violin Collegium Musicum 90 | I15: =VLOOKUP(D15,Categories!$A$1:$D$53,MATCH(I$3,Categories!$A$1:$D$1,0),FALSE) -> Sampler | J15: =IF(OR(AND(E15>1000000, E15<5000000), C15 = ".mp3"),"Yes","No") -> No | K15: {=_xlfn.IFS(C15=".mp3","Yes",AND(E15>1000000,E15<5000000),"Yes",TRUE,"No")} -> No | L15: {=_xlfn.SWITCH(C15,".wma","This is a WMA file!",".mp3","MP3 are great!","This is a different type of file")} -> This is a WMA file!
... A31: 46 | B31: 13 Remember not, Lord our offences.wma | C31: .wma | D31: \1000 Years Of Sacred Music Disc 4\ | E31: 4175750 | F31: 41701.617 | G31: Remember not, Lord our offences | H31: The Choir of Clare College Cambridge | I31: =VLOOKUP(D31,Categories!$A$1:$D$53,MATCH(I$3,Categories!$A$1:$D$1,0),FALSE) -> Sampler | J31: =IF(OR(AND(E31>1000000, E31<5000000), C31 = ".mp3"),"Yes","No") -> Yes | K31: {=_xlfn.IFS(C31=".mp3","Yes",AND(E31>1000000,E31<5000000),"Yes",TRUE,"No")} -> Yes | L31: {=_xlfn.SWITCH(C31,".wma","This is a WMA file!",".mp3","MP3 are great!","This is a different type of file")} -> This is a WMA file!
A32: 47 | B32: 14 Hear my prayer, O Lord.wma | C32: .wma | D32: \1000 Years Of Sacred Music Disc 4\ | E32: 2976700 | F32: 41701.617 | G32: Hear my prayer, O Lord | H32: The Choir of Clare College Cambridge | I32: =VLOOKUP(D32,Categories!$A$1:$D$53,MATCH(I$3,Categories!$A$1:$D$1,0),FALSE) -> Sampler | J32: =IF(OR(AND(E32>1000000, E32<5000000), C32 = ".mp3"),"Yes","No") -> Yes | L32: {=_xlfn.SWITCH(C32,".wma","This is a WMA file!",".mp3","MP3 are great!","This is a different type of file")} -> This is a WMA file!
A33: 48 | B33: 15 Funeral March.wma | C33: .wma | D33: \1000 Years Of Sacred Music Disc 4\ | E33: 3119850 | F33: 41701.617 | G33: Funeral March | H33: The Choir of Clare College Cambridge | I33: =VLOOKUP(D33,Categories!$A$1:$D$53,MATCH(I$3,Categories!$A$1:$D$1,0),FALSE) -> Sampler | J33: =IF(OR(AND(E33>1000000, E33<5000000), C33 = ".mp3"),"Yes","No") -> Yes | L33: {=_xlfn.SWITCH(C33,".wma","This is a WMA file!",".mp3","MP3 are great!","This is a different type of file")} -> This is a WMA file!
A34: 49 | B34: 16 Man that is born of a woman.wma | C34: .wma | D34: \1000 Years Of Sacred Music Disc 4\ | E34: 3477798 | F34: 41701.617 | G34: Man that is born of a woman | H34: The Choir of Clare College Cambridge | I34: =VLOOKUP(D34,Categories!$A$1:$D$53,MATCH(I$3,Categories!$A$1:$D$1,0),FALSE) -> Sampler | J34: =IF(OR(AND(E34>1000000, E34<5000000), C34 = ".mp3"),"Yes","No") -> Yes | L34: {=_xlfn.SWITCH(C34,".wma","This is a WMA file!",".mp3","MP3 are great!","This is a different type of file")} -> This is a WMA file!
A35: 50 | B35: 17 In the midst of life.wma | C35: .wma | D35: \1000 Years Of Sacred Music Disc 4\ | E35: 5330020 | F35: 41701.617 | G35: In the midst of life | H35: The Choir of Clare College Cambridge | I35: =VLOOKUP(D35,Categories!$A$1:$D$53,MATCH(I$3,Categories!$A$1:$D$1,0),FALSE) -> Sampler | J35: =IF(OR(AND(E35>1000000, E35<5000000), C35 = ".mp3"),"Yes","No") -> No | L35: {=_xlfn.SWITCH(C35,".wma","This is a WMA file!",".mp3","MP3 are great!","This is a different type of file")} -> This is a WMA file!
A36: 51 | B36: 18 Canzona.wma | C36: .wma | D36: \1000 Years Of Sacred Music Disc 4\ | E36: 3477812 | F36: 41701.617 | G36: Canzona | H36: The Choir of Clare College, Cambridge & Baroque Brass of London | I36: =VLOOKUP(D36,Categories!$A$1:$D$53,MATCH(I$3,Categories!$A$1:$D$1,0),FALSE) -> Sampler | J36: =IF(OR(AND(E36>1000000, E36<5000000), C36 = ".mp3"),"Yes","No") -> Yes | L36: {=_xlfn.SWITCH(C36,".wma","This is a WMA file!",".mp3","MP3 are great!","This is a different type of file")} -> This is a WMA file!
A37: 52 | B37: 19 Thou knowest, Lord.wma | C37: .wma | D37: \1000 Years Of Sacred Music Disc 4\ | E37: 4139932 | F37: 41701.617 | G37: Thou knowest, Lord | H37: The Choir of Clare College Cambridge | I37: =VLOOKUP(D37,Categories!$A$1:$D$53,MATCH(I$3,Categories!$A$1:$D$1,0),FALSE) -> Sampler | J37: =IF(OR(AND(E37>1000000, E37<5000000), C37 = ".mp3"),"Yes","No") -> Yes | L37: {=_xlfn.SWITCH(C37,".wma","This is a WMA file!",".mp3","MP3 are great!","This is a different type of file")} -> This is a WMA file!
A38: 53 | B38: 20 Funeral March.wma | C38: .wma | D38: \1000 Years Of Sacred Music Disc 4\ | E38: 1876078 | F38: 41701.617 | G38: Funeral March | H38: The Choir of Clare College Cambridge | I38: =VLOOKUP(D38,Categories!$A$1:$D$53,MATCH(I$3,Categories!$A$1:$D$1,0),FALSE) -> Sampler | J38: =IF(OR(AND(E38>1000000, E38<5000000), C38 = ".mp3"),"Yes","No") -> Yes | L38: {=_xlfn.SWITCH(C38,".wma","This is a WMA file!",".mp3","MP3 are great!","This is a different type of file")} -> This is a WMA file!
A39: 56 | B39: 01 Lamento d' Ariannna.wma | C39: .wma | D39: \1991 Collection\ | E39: 19547912 | F39: 40049.556 | G39: Lamento d' Ariannna | H39: Virgin Classics | I39: =VLOOKUP(D39,Categories!$A$1:$D$53,MATCH(I$3,Categories!$A$1:$D$1,0),FALSE) -> Sampler | J39: =IF(OR(AND(E39>1000000, E39<5000000), C39 = ".mp3"),"Yes","No") -> No | L39: {=_xlfn.SWITCH(C39,".wma","This is a WMA file!",".mp3","MP3 are great!","This is a different type of file")} -> This is a WMA file!
A40: 57 | B40: 02 Horn Concerto No. 3.wma | C40: .wma | D40: \1991 Collection\ | E40: 9365398 | F40: 40049.556 | G40: Horn Concerto No. 3 | H40: Virgin Classics | I40: =VLOOKUP(D40,Categories!$A$1:$D$53,MATCH(I$3,Categories!$A$1:$D$1,0),FALSE) -> Sampler | J40: =IF(OR(AND(E40>1000000, E40<5000000), C40 = ".mp3"),"Yes","No") -> No | L40: {=_xlfn.SWITCH(C40,".wma","This is a WMA file!",".mp3","MP3 are great!","This is a different type of file")} -> This is a WMA file!
A41: 58 | B41: 03 Horn Concerto No. 3.wma | C41: .wma | D41: \1991 Collection\ | E41: 7038918 | F41: 40049.556 | G41: Horn Concerto No. 3 | H41: Virgin Classics | I41: =VLOOKUP(D41,Categories!$A$1:$D$53,MATCH(I$3,Categories!$A$1:$D$1,0),FALSE) -> Sampler | J41: =IF(OR(AND(E41>1000000, E41<5000000), C41 = ".mp3"),"Yes","No") -> No | L41: {=_xlfn.SWITCH(C41,".wma","This is a WMA file!",".mp3","MP3 are great!","This is a different type of file")} -> This is a WMA file!
A42: 59 | B42: 04 Horn Concerto No. 3.wma | C42: .wma | D42: \1991 Collection\ | E42: 5669874 | F42: 40049.556 | G42: Horn Concerto No. 3 | H42: Virgin Classics | I42: =VLOOKUP(D42,Categories!$A$1:$D$53,MATCH(I$3,Categories!$A$1:$D$1,0),FALSE) -> Sampler | J42: =IF(OR(AND(E42>1000000, E42<5000000), C42 = ".mp3"),"Yes","No") -> No | L42: {=_xlfn.SWITCH(C42,".wma","This is a WMA file!",".mp3","MP3 are great!","This is a different type of file")} -> This is a WMA file!
A43: 60 | B43: 05 St. Paul's Suite.wma | C43: .wma | D43: \1991 Collection\ | E43: 4435042 | F43: 40049.556 | G43: St. Paul's Suite | H43: Virgin Classics | I43: =VLOOKUP(D43,Categories!$A$1:$D$53,MATCH(I$3,Categories!$A$1:$D$1,0),FALSE) -> Sampler | J43: =IF(OR(AND(E43>1000000, E43<5000000), C43 = ".mp3"),"Yes","No") -> Yes | L43: {=_xlfn.SWITCH(C43,".wma","This is a WMA file!",".mp3","MP3 are great!","This is a different type of file")} -> This is a WMA file!
... A148: 268 | B148: 14 Lady Macbeth of Mtsensk.wma | C148: .wma | D148: \A Night At The Opera II\ | E148: 9177568 | F148: 39258.845 | G148: Lady Macbeth of Mtsensk | H148: Various Artists | I148: =VLOOKUP(D148,Categories!$A$1:$D$53,MATCH(I$3,Categories!$A$1:$D$1,0),FALSE) -> Opera | J148: =IF(OR(AND(E148>1000000, E148<5000000), C148 = ".mp3"),"Yes","No") -> No | L148: {=_xlfn.SWITCH(C148,".wma","This is a WMA file!",".mp3","MP3 are great!","This is a different type of file")} -> This is a WMA file!
A149: 269 | B149: 14 Track 14.wma | C149: .wma | D149: \A Night At The Opera II\ | E149: 8792612 | F149: 39258.847 | G149: Track 14 | I149: =VLOOKUP(D149,Categories!$A$1:$D$53,MATCH(I$3,Categories!$A$1:$D$1,0),FALSE) -> Opera | J149: =IF(OR(AND(E149>1000000, E149<5000000), C149 = ".mp3"),"Yes","No") -> No | L149: {=_xlfn.SWITCH(C149,".wma","This is a WMA file!",".mp3","MP3 are great!","This is a different type of file")} -> This is a WMA file!
A150: 270 | B150: 15 Track 15.wma | C150: .wma | D150: \A Night At The Opera II\ | E150: 9794788 | F150: 39258.847 | G150: Track 15 | I150: =VLOOKUP(D150,Categories!$A$1:$D$53,MATCH(I$3,Categories!$A$1:$D$1,0),FALSE) -> Opera | J150: =IF(OR(AND(E150>1000000, E150<5000000), C150 = ".mp3"),"Yes","No") -> No | L150: {=_xlfn.SWITCH(C150,".wma","This is a WMA file!",".mp3","MP3 are great!","This is a different type of file")} -> This is a WMA file!
A151: 271 | B151: 15 Turandot.wma | C151: .wma | D151: \A Night At The Opera II\ | E151: 9293852 | F151: 39258.845 | G151: Turandot | H151: Various Artists | I151: =VLOOKUP(D151,Categories!$A$1:$D$53,MATCH(I$3,Categories!$A$1:$D$1,0),FALSE) -> Opera | J151: =IF(OR(AND(E151>1000000, E151<5000000), C151 = ".mp3"),"Yes","No") -> No | L151: {=_xlfn.SWITCH(C151,".wma","This is a WMA file!",".mp3","MP3 are great!","This is a different type of file")} -> This is a WMA file!
A152: 272 | B152: 16 Pellease et Melisande.wma | C152: .wma | D152: \A Night At The Opera II\ | E152: 12846234 | F152: 39258.845 | G152: Pellease et Melisande | H152: Various Artists | I152: =VLOOKUP(D152,Categories!$A$1:$D$53,MATCH(I$3,Categories!$A$1:$D$1,0),FALSE) -> Opera | J152: =IF(OR(AND(E152>1000000, E152<5000000), C152 = ".mp3"),"Yes","No") -> No | L152: {=_xlfn.SWITCH(C152,".wma","This is a WMA file!",".mp3","MP3 are great!","This is a different type of file")} -> This is a WMA file!
A153: 273 | B153: 17 Don Giovanni.wma | C153: .wma | D153: \A Night At The Opera II\ | E153: 7656374 | F153: 39258.845 | G153: Don Giovanni | H153: Various Artists | I153: =VLOOKUP(D153,Categories!$A$1:$D$53,MATCH(I$3,Categories!$A$1:$D$1,0),FALSE) -> Opera | J153: =IF(OR(AND(E153>1000000, E153<5000000), C153 = ".mp3"),"Yes","No") -> No | L153: {=_xlfn.SWITCH(C153,".wma","This is a WMA file!",".mp3","MP3 are great!","This is a different type of file")} -> This is a WMA file!
A154: 274 | B154: 18 Don Giovanni.wma | C154: .wma | D154: \A Night At The Opera II\ | E154: 5660970 | F154: 39258.845 | G154: Don Giovanni | H154: Various Artists | I154: =VLOOKUP(D154,Categories!$A$1:$D$53,MATCH(I$3,Categories!$A$1:$D$1,0),FALSE) -> Opera | J154: =IF(OR(AND(E154>1000000, E154<5000000), C154 = ".mp3"),"Yes","No") -> No | L154: {=_xlfn.SWITCH(C154,".wma","This is a WMA file!",".mp3","MP3 are great!","This is a different type of file")} -> This is a WMA file!
A155: 278 | B155: 01 Adagio, From Clarinet Concerto.wma | C155: .wma | D155: \Adagio Serene Classical Music for a Peaceful Mind Disc 1\ | E155: 21579002 | F155: 39261.307 | G155: Adagio, From Clarinet Concerto | H155: De Boer, Harmen; Lev Markiz; Nieuw Sinfonietta Amsterdam | I155: =VLOOKUP(D155,Categories!$A$1:$D$53,MATCH(I$3,Categories!$A$1:$D$1,0),FALSE) -> Sampler | J155: =IF(OR(AND(E155>1000000, E155<5000000), C155 = ".mp3"),"Yes","No") -> No | L155: {=_xlfn.SWITCH(C155,".wma","This is a WMA file!",".mp3","MP3 are great!","This is a different type of file")} -> This is a WMA file!
A156: 279 | B156: 02 Adagio for Strings.wma | C156: .wma | D156: \Adagio Serene Classical Music for a Peaceful Mind Disc 1\ | E156: 12676186 | F156: 39261.307 | G156: Adagio for Strings | H156: London Baroque Soloists | I156: =VLOOKUP(D156,Categories!$A$1:$D$53,MATCH(I$3,Categories!$A$1:$D$1,0),FALSE) -> Sampler | J156: =IF(OR(AND(E156>1000000, E156<5000000), C156 = ".mp3"),"Yes","No") -> No | L156: {=_xlfn.SWITCH(C156,".wma","This is a WMA file!",".mp3","MP3 are great!","This is a different type of file")} -> This is a WMA file!
A157: 280 | B157: 03 Adagio, From Sonata Pathetique.wma | C157: .wma | D157: \Adagio Serene Classical Music for a Peaceful Mind Disc 1\ | E157: 16908608 | F157: 39261.307 | G157: Adagio, From Sonata Pathetique | H157: Misha Goldstein | I157: =VLOOKUP(D157,Categories!$A$1:$D$53,MATCH(I$3,Categories!$A$1:$D$1,0),FALSE) -> Sampler | J157: =IF(OR(AND(E157>1000000, E157<5000000), C157 = ".mp3"),"Yes","No") -> No | L157: {=_xlfn.SWITCH(C157,".wma","This is a WMA file!",".mp3","MP3 are great!","This is a different type of file")} -> This is a WMA file!
A158: 281 | B158: 04 Andante, From Piano Concerto No. 21 'Elvira Madigan'.wma | C158: .wma | D158: \Adagio Serene Classical Music for a Peaceful Mind Disc 1\ | E158: 13687450 | F158: 39261.307 | G158: Andante, From Piano Concerto No. 21 "Elvira Madigan" | H158: Derek Han; Paul Freeman; The Philharmonia Orchestra | I158: =VLOOKUP(D158,Categories!$A$1:$D$53,MATCH(I$3,Categories!$A$1:$D$1,0),FALSE) -> Sampler | J158: =IF(OR(AND(E158>1000000, E158<5000000), C158 = ".mp3"),"Yes","No") -> No | L158: {=_xlfn.SWITCH(C158,".wma","This is a WMA file!",".mp3","MP3 are great!","This is a different type of file")} -> This is a WMA file!
A159: 283 | B159: 01 Se qual gurriero io fossi... celeste Aida.wma | C159: .wma | D159: \Aida Disc 1\ | E159: 6770178 | F159: 39258.708 | G159: Se qual gurriero io fossi... celeste Aida | H159: Giuseppe Verdi | I159: =VLOOKUP(D159,Categories!$A$1:$D$53,MATCH(I$3,Categories!$A$1:$D$1,0),FALSE) -> Opera | J159: =IF(OR(AND(E159>1000000, E159<5000000), C159 = ".mp3"),"Yes","No") -> No | L159: {=_xlfn.SWITCH(C159,".wma","This is a WMA file!",".mp3","MP3 are great!","This is a different type of file")} -> This is a WMA file!
A160: 284 | B160: 02 Or, di vulcano al tempio.wma | C160: .wma | D160: \Aida Disc 1\ | E160: 6421680 | F160: 39258.708 | G160: Or, di vulcano al tempio | H160: Giuseppe Verdi | I160: =VLOOKUP(D160,Categories!$A$1:$D$53,MATCH(I$3,Categories!$A$1:$D$1,0),FALSE) -> Opera | J160: =IF(OR(AND(E160>1000000, E160<5000000), C160 = ".mp3"),"Yes","No") -> No | L160: {=_xlfn.SWITCH(C160,".wma","This is a WMA file!",".mp3","MP3 are great!","This is a different type of file")} -> This is a WMA file!
...

Sheet Sheet1

Sheet a b c d e f g
A1: File extension
A2: .wma
A3: .m4b
A4: .mp3
B5: a b c d e f g value

Sheet New sheet
B5: New sheet value

Sheet Combo
A1: RegionName | B1: East of England
A3: Row Labels | B3: Sum of DetachedIndex | C3: Average of DetachedAveragePrice
A4: 1995 | B4: 305.15359 | C4: 86814.256
A5: 1996 | B5: 310.5454 | C5: 88348.192
A6: 1997 | B6: 345.96489 | C6: 98424.811
A7: 1998 | B7: 384.46163 | C7: 109376.89
A8: 1999 | B8: 423.31644 | C8: 120430.83
A9: 2000 | B9: 505.90822 | C9: 143927.67
A10: 2001 | B10: 577.33696 | C10: 164248.69
A11: 2002 | B11: 698.56032 | C11: 198735.97
A12: 2003 | B12: 815.49752 | C12: 232003.86
A13: 2004 | B13: 890.00947 | C13: 253202.03
A14: 2005 | B14: 919.57443 | C14: 261613.08
A15: 2006 | B15: 965.40634 | C15: 274651.96
... A32: Grand Total | B32: 27765.464 | C32: 282110.63

Sheet Sunburst chart
A1: RegionName | B1: East of England
A3: Years | B3: Quarters | C3: Date | D3: Average of DetachedIndex
A4: 1995 | D4: 25.429466
A5: 1996 | D5: 25.878784
A6: 1997 | D6: 28.830408
A7: 1998 | D7: 32.038469
A8: 1999 | D8: 35.27637
A9: 2000 | B9: Qtr1 | D9: 38.942611
B10: Qtr2 | C10: Apr | D10: 40.795431
C11: May | D11: 41.735135
C12: Jun | D12: 41.742284
B13: Qtr3 | D13: 44.07773
B14: Qtr4 | D14: 44.191451
A15: 2000 Total | D15: 42.159019
A16: 2001 | D16: 48.111413
A17: 2002 | D17: 58.21336
A18: 2003 | D18: 67.958126
A19: 2004 | D19: 74.167456
A20: 2005 | D20: 76.631203
A21: 2006 | D21: 80.450528
A22: 2007 | D22: 87.617405
A23: 2008 | D23: 84.785197
A24: 2009 | D24: 77.182689
A25: 2010 | D25: 84.367732
A26: 2011 | D26: 84.181661
... A38: Grand Total | D38: 82.63531

Sheet Waterfall chart
A1: RegionName | C1: East of England
A3: Year | B3: Difference | C3: Average of DetachedAveragePrice
A4: 1995 | B4: =C4 -> 86814.256 | C4: 86814.256
A5: 1996 | B5: =C5-C4 -> 1533.9362 | C5: 88348.192
A6: 1997 | B6: =C6-C5 -> 10076.619 | C6: 98424.811
A7: 1998 | B7: =C7-C6 -> 10952.077 | C7: 109376.89
A8: 1999 | B8: =C8-C7 -> 11053.947 | C8: 120430.83
A9: 2000 | B9: =C9-C8 -> 23496.838 | C9: 143927.67
A10: 2001 | B10: =C10-C9 -> 20321.021 | C10: 164248.69
A11: 2002 | B11: =C11-C10 -> 34487.276 | C11: 198735.97
A12: 2003 | B12: =C12-C11 -> 33267.888 | C12: 232003.86
A13: 2004 | B13: =C13-C12 -> 21198.178 | C13: 253202.03
A14: 2005 | B14: =C14-C13 -> 8411.0428 | C14: 261613.08
A15: 2006 | B15: =C15-C14 -> 13038.886 | C15: 274651.96
A16: 2007 | B16: =C16-C15 -> 24467.169 | C16: 299119.13
... A31: 2022 | B31: =C31-C30 -> 59739.858 | C31: 546223.05
A32: Grand Total | C32: 282110.63

Sheet Funnel
A1: Funnel chart data
A3: Number of people who watch…
A5: Section | B5: Number of people
A6: The introduction | B6: 11417
A7: All of section 1 | B7: 9003
A8: All of section 2 | B8: 6798
A9: All of section 3 | B9: 5909
A10: All of section 4 | B10: 2979

Sheet HPIRegions
A1: Date | B1: RegionName | C1: AreaCode | D1: DetachedAveragePrice | E1: DetachedIndex | F1: DetachedMonthlyChange | G1: DetachedAnnualChange | H1: SemiDetachedAveragePrice | I1: SemiDetachedIndex | J1: SemiDetachedMonthlyChange | K1: SemiDetachedAnnualChange | L1: TerracedAveragePrice | M1: TerracedIndex | N1: TerracedMonthlyChange | O1: TerracedAnnualChange | P1: FlatAveragePrice | Q1: FlatIndex | R1: FlatMonthlyChange | S1: FlatAnnualChange
A2: 34700 | B2: England | C2: E92000001 | D2: 86314.159 | E2: 28.257874 | H2: 51533.225 | I2: 27.436474 | L2: 41489.824 | M2: 25.279664 | P2: 45218.541 | Q2: 23.762969
A3: 34700 | B3: East Midlands | C3: E12000004 | D3: 68923.938 | E3: 30.745262 | H3: 41227.496 | I3: 29.322019 | L3: 32870.494 | M3: 28.249263 | P3: 30954.761 | Q3: 32.880529
A4: 34700 | B4: North East | C4: E12000001 | D4: 73456.036 | E4: 37.782734 | H4: 42769.486 | I4: 36.170007 | L4: 33036.428 | M4: 34.6604 | P4: 30566.131 | Q4: 36.472373
A5: 34700 | B5: East of England | C5: E12000006 | D5: 88394.244 | E5: 25.892273 | H5: 56278.555 | I5: 24.527416 | L5: 45356.649 | M5: 23.68537 | P5: 40450.344 | Q5: 26.116976
A6: 34700 | B6: South East | C6: E12000008 | D6: 113412.5 | E6: 24.938444 | H6: 66624.949 | I6: 23.874543 | L6: 51088.694 | M6: 23.184027 | P6: 43145.792 | Q6: 25.379798
A7: 34700 | B7: South West | C7: E12000009 | D7: 87928.855 | E7: 26.691252 | H7: 54297.329 | I7: 25.505373 | L7: 43403.732 | M7: 24.528639 | P7: 37858.523 | Q7: 26.701796
A8: 34700 | B8: Yorkshire and The Humber | C8: E12000003 | D8: 74264.805 | E8: 34.084619 | H8: 43825.651 | I8: 32.737774 | L8: 34857.023 | M8: 32.049691 | P8: 34607.698 | Q8: 34.714146
A9: 34700 | B9: North West | C9: E12000002 | D9: 79786.629 | E9: 33.95164 | H9: 46063.025 | I9: 32.234016 | L9: 32974.568 | M9: 31.588852 | P9: 34432.826 | Q9: 34.028771
A10: 34700 | B10: West Midlands Region | C10: E12000005 | D10: 81999.453 | E10: 31.385024 | H10: 46457.183 | I10: 30.453267 | L10: 36678.168 | M10: 29.405104 | P10: 34983.156 | Q10: 33.326469
A11: 34700 | B11: London | C11: E12000007 | D11: 161449.31 | E11: 21.715622 | H11: 95897.529 | I11: 20.321394 | L11: 73705.966 | M11: 18.023197 | P11: 64618.572 | Q11: 17.858341
A12: 34731 | B12: England | C12: E92000001 | D12: 84877.175 | E12: 27.787429 | F12: -1.6648303 | H12: 52026.478 | I12: 27.699083 | J12: 0.95715361 | L12: 41674.394 | M12: 25.392122 | N12: 0.44485552 | P12: 44292.045 | Q12: 23.276083 | R12: -2.0489297
A13: 34731 | B13: Yorkshire and The Humber | C13: E12000003 | D13: 72746.955 | E13: 33.387986 | F13: -2.0438361 | H13: 43978.737 | I13: 32.85213 | J13: 0.34930771 | L13: 34604.003 | M13: 31.817049 | N13: -0.72588085 | P13: 34490.875 | Q13: 34.596964 | R13: -0.33756355
A14: 34731 | B14: North East | C14: E12000001 | D14: 73262.341 | E14: 37.683105 | F14: -0.26368862 | H14: 43743.661 | I14: 36.993864 | J14: 2.2777336 | L14: 33347.299 | M14: 34.986553 | N14: 0.94099503 | P14: 30914.341 | Q14: 36.887867 | R14: 1.1392024
A15: 34731 | B15: East Midlands | C15: E12000004 | D15: 68634.751 | E15: 30.616263 | F15: -0.41957439 | H15: 42051.338 | I15: 29.907956 | J15: 1.9982814 | L15: 33423.749 | M15: 28.724737 | N15: 1.6831375 | P15: 31600.058 | Q15: 33.565972 | R15: 2.0846452
A16: 34731 | B16: West Midlands Region | C16: E12000005 | D16: 81631.33 | E16: 31.244126 | F16: -0.4489336 | H16: 47702.774 | I16: 31.269768 | J16: 2.6811584 | L16: 37531.185 | M16: 30.088973 | N16: 2.3256808 | P16: 35426.309 | Q16: 33.748636 | R16: 1.2667607
A17: 34731 | B17: East of England | C17: E12000006 | D17: 86549.888 | E17: 25.352028 | F17: -2.0865117 | H17: 56551.511 | I17: 24.646376 | J17: 0.48500861 | L17: 45706.043 | M17: 23.867825 | N17: 0.77032566 | P17: 40645.507 | Q17: 26.242984 | R17: 0.4824736
A18: 34731 | B18: South East | C18: E12000008 | D18: 110933.37 | E18: 24.393306 | F18: -2.185933 | H18: 66862.12 | I18: 23.959531 | J18: 0.35597853 | L18: 51209.761 | M18: 23.238967 | N18: 0.23697408 | P18: 43066.917 | Q18: 25.333401 | R18: -0.18280974
A19: 34731 | B19: South West | C19: E12000009 | D19: 86203.595 | E19: 26.16754 | F19: -1.962109 | H19: 54515.866 | I19: 25.608028 | J19: 0.40248236 | L19: 43345.323 | M19: 24.495631 | N19: -0.13457208 | P19: 37517.999 | Q19: 26.461623 | R19: -0.89946488
A20: 34731 | B20: North West | C20: E12000002 | D20: 78163.295 | E20: 33.260862 | F20: -2.0345941 | H20: 46447.545 | I20: 32.503096 | J20: 0.83476929 | L20: 33033.31 | M20: 31.645126 | N20: 0.17814389 | P20: 34092.942 | Q20: 33.692875 | R20: -0.98709267
A21: 34731 | B21: London | C21: E12000007 | D21: 157449.44 | E21: 21.177623 | F21: -2.4774752 | H21: 96084.273 | I21: 20.360966 | J21: 0.19473255 | L21: 73756.54 | M21: 18.035563 | N21: 0.068616466 | P21: 60358.673 | Q21: 16.681052 | R21: -6.5923769
A22: 34759 | B22: England | C22: E92000001 | D22: 84593.589 | E22: 27.694587 | F22: -0.33411315 | H22: 51845.599 | I22: 27.602783 | J22: -0.34766718 | L22: 41906.419 | M22: 25.533494 | N22: 0.55675709 | P22: 45074.384 | Q22: 23.687213 | R22: 1.7663208
A23: 34759 | B23: East of England | C23: E12000006 | D23: 85654.201 | E23: 25.089665 | F23: -1.034879 | H23: 56014.718 | I23: 24.41243 | J23: -0.9492099 | L23: 45680.882 | M23: 23.854686 | N23: -0.055048675 | P23: 40160.669 | Q23: 25.929945 | R23: -1.1928452
... A121: 35034 | B121: North West | C121: E12000002 | D121: 77841.276 | E121: 33.123833 | F121: -0.36063792 | H121: 45852.331 | I121: 32.086576 | J121: -0.049591107 | L121: 32462.144 | M121: 31.097963 | N121: 0.53935223 | P121: 33856.918 | Q121: 33.459621 | R121: -0.54561906
A122: 35065 | B122: England | C122: E92000001 | D122: 84999.634 | E122: 27.82752 | F122: 0.4929192 | G122: -1.5229545 | H122: 50961.092 | I122: 27.131868 | J122: -1.5041712 | K122: -1.1102224 | L122: 40553.078 | M122: 24.708906 | N122: -1.7880642 | O122: -2.2577736 | P122: 44528.436 | Q122: 23.40031 | R122: -1.4128339 | S122: -1.5261541
A123: 35065 | B123: London | C123: E12000007 | D123: 159926.34 | E123: 21.510777 | F123: 0.70967273 | G123: -0.94330653 | H123: 96393.427 | I123: 20.426478 | J123: -0.040745365 | K123: 0.51711226 | L123: 74754.027 | M123: 18.279477 | N123: 0.67400652 | O123: 1.4219496 | P123: 65869.828 | Q123: 18.204145 | R123: -0.24034282 | S123: 1.9363711
A124: 35065 | B124: West Midlands Region | C124: E12000005 | D124: 81547.188 | E124: 31.211921 | F124: 0.076787749 | G124: -0.55154649 | H124: 46316.283 | I124: 30.360906 | J124: -2.4369268 | K124: -0.30329 | L124: 35797.226 | M124: 28.698848 | N124: -3.5710851 | O124: -2.4018152 | P124: 34002.542 | Q124: 32.392294 | R124: -2.9925734 | S124: -2.8031016
A125: 35065 | B125: South East | C125: E12000008 | D125: 114170.73 | E125: 25.105174 | F125: 1.8323872 | G125: 0.66856615 | H125: 67144.411 | I125: 24.060688 | J125: -0.50821873 | K125: 0.77968065 | L125: 50935.046 | M125: 23.114301 | N125: -1.1660717 | O125: -0.300749 | P125: 42399.662 | Q125: 24.940899 | R125: -2.2584604 | S125: -1.7293221
A126: 35065 | B126: North East | C126: E12000001 | D126: 72054.317 | E126: 37.061748 | F126: -1.627678 | G126: -1.9082427 | H126: 41804.708 | I126: 35.354098 | J126: -3.847219 | K126: -2.2557612 | L126: 31699.678 | M126: 33.25794 | N126: -4.3651141 | O126: -4.0462902 | P126: 29318.309 | Q126: 34.983437 | R126: -3.280357 | S126: -4.0823663
A127: 35065 | B127: North West | C127: E12000002 | D127: 78376.56 | E127: 33.351613 | F127: 0.68766073 | G127: -1.7673002 | H127: 45104.971 | I127: 31.563588 | J127: -1.6299284 | K127: -2.0798768 | L127: 31471.988 | M127: 30.149417 | N127: -3.0501873 | O127: -4.556783 | P127: 33028.27 | Q127: 32.640697 | R127: -2.4474988 | S127: -4.0791178
A128: 35065 | B128: South West | C128: E12000009 | D128: 85745.697 | E128: 26.028543 | F128: 1.5340432 | G128: -2.4828686 | H128: 53409.179 | I128: 25.088178 | J128: 0.050783994 | K128: -1.6357151 | L128: 42325.003 | M128: 23.91902 | N128: 0.38261914 | O128: -2.4853367 | P128: 36320.925 | Q128: 25.617321 | R128: -0.44207527 | S128: -4.0614317
A129: 35065 | B129: East Midlands | C129: E12000004 | D129: 67519.173 | E129: 30.118631 | F129: -1.2724059 | G129: -2.0381388 | H129: 40711.106 | I129: 28.95475 | J129: -2.5761277 | K129: -1.2525386 | L129: 31890.138 | M129: 27.406734 | N129: -2.886531 | O129: -2.9824796 | P129: 29994.669 | Q129: 31.860707 | R129: -3.4165677 | S129: -3.1015995
A130: 35065 | B130: East of England | C130: E12000006 | D130: 85384.647 | E130: 25.010708 | F130: 0.1717689 | G130: -3.4047433 | H130: 54820.992 | I130: 23.892178 | J130: -1.4358162 | K130: -2.5899089 | L130: 44142.937 | M130: 23.051567 | N130: -1.3630436 | O130: -2.6759291 | P130: 39108.061 | Q130: 25.250324 | R130: -0.90748049 | S130: -3.3183484
A131: 35065 | B131: Yorkshire and The Humber | C131: E12000003 | D131: 72575.161 | E131: 33.309139 | F131: -0.57738476 | G131: -2.2751617 | H131: 42913.192 | I131: 32.056167 | J131: -2.4261793 | K131: -2.0820203 | L131: 33434.847 | M131: 30.742055 | N131: -2.9390597 | O131: -4.0800273 | P131: 33009.297 | Q131: 33.110828 | R131: -2.8569863 | S131: -4.6186302
A132: 35096 | B132: England | C132: E92000001 | D132: 84344.256 | E132: 27.61296 | F132: -0.77103523 | G132: -0.62786995 | H132: 51381.117 | I132: 27.355491 | J132: 0.82420737 | K132: -1.2404462 | L132: 40833.661 | M132: 24.879865 | N132: 0.69189014 | O132: -2.0173858 | P132: 44925.827 | Q132: 23.609144 | R132: 0.8924417 | S132: 1.4309157
A133: 35096 | B133: East of England | C133: E12000006 | D133: 85480.883 | E133: 25.038897 | F133: 0.11270817 | G133: -1.2351321 | H133: 55487.531 | I133: 24.18267 | J133: 1.2158464 | K133: -1.8814353 | L133: 44379.744 | M133: 23.175228 | N133: 0.53645418 | O133: -2.9018023 | P133: 39011.841 | Q133: 25.188199 | R133: -0.24603625 | S133: -4.0193018
... A3361: 44896 | B3361: South West | C3361: E12000009 | D3361: 523096.83 | E3361: 158.78872 | F3361: -2.613131 | G3361: 8.1845349 | H3361: 343237.24 | I3361: 161.23067 | J3361: -1.5827391 | K3361: 10.827791 | L3361: 278943.44 | M3361: 157.6386 | N3361: -1.4118709 | O3361: 9.7212418 | P3361: 196336.74 | Q3361: 138.47724 | R3361: -1.25788 | S3361: 6.3924186

Sheet HPIAdmins
A1: Date | B1: RegionName | C1: AreaCode | D1: DetachedAveragePrice | E1: DetachedIndex | F1: DetachedMonthlyChange | G1: DetachedAnnualChange | H1: SemiDetachedAveragePrice | I1: SemiDetachedIndex | J1: SemiDetachedMonthlyChange | K1: SemiDetachedAnnualChange | L1: TerracedAveragePrice | M1: TerracedIndex | N1: TerracedMonthlyChange | O1: TerracedAnnualChange | P1: FlatAveragePrice | Q1: FlatIndex | R1: FlatMonthlyChange | S1: FlatAnnualChange
A2: 34700 | B2: South Yorkshire | C2: E11000003 | D2: 63180.143 | E2: 34.097127 | H2: 38282.902 | I2: 31.822319 | L2: 30663.672 | M2: 30.426527 | P2: 30488.101 | Q2: 34.01721
A3: 34700 | B3: Merseyside | C3: E11000002 | D3: 76375.699 | E3: 35.757471 | H3: 46160.26 | I3: 33.813395 | L3: 31784.046 | M3: 32.818059 | P3: 32254.461 | Q3: 36.377876
A4: 34700 | B4: West Midlands | C4: E11000005 | D4: 83146.6 | E4: 33.105095 | H4: 46990.726 | I4: 31.312954 | L4: 36661.119 | M4: 29.67506 | P4: 34743.344 | Q4: 34.098272
A5: 34700 | B5: Tyne and Wear | C5: E11000007 | D5: 75741.97 | E5: 33.640536 | H5: 44133.862 | I5: 32.668156 | L5: 35921.426 | M5: 31.30423 | P5: 31360.279 | Q5: 34.825289
A6: 34700 | B6: Greater Manchester | C6: E11000001 | D6: 75577.298 | E6: 32.979615 | H6: 44548.707 | I6: 30.164735 | L6: 32650.493 | M6: 30.064445 | P6: 34746.621 | Q6: 31.742731
A7: 34700 | B7: West Yorkshire | C7: E11000006 | D7: 78113.234 | E7: 34.756277 | H7: 45113.135 | I7: 32.938652 | L7: 35415.154 | M7: 32.82785 | P7: 34744.711 | Q7: 35.436644
A8: 34731 | B8: West Midlands | C8: E11000005 | D8: 83220.21 | E8: 33.134402 | F8: 0.088529483 | H8: 47753.762 | I8: 31.821414 | J8: 1.6238019 | L8: 37153.244 | M8: 30.073407 | N8: 1.3423639 | P8: 35098.826 | Q8: 34.447153 | R8: 1.0231651
A9: 34731 | B9: West Yorkshire | C9: E11000006 | D9: 77651.129 | E9: 34.550664 | F9: -0.5915836 | H9: 45431.004 | I9: 33.170739 | J9: 0.70460338 | L9: 35437.952 | M9: 32.848982 | N9: 0.064372216 | P9: 34910.65 | Q9: 35.605887 | R9: 0.47759403
A10: 34731 | B10: South Yorkshire | C10: E11000003 | D10: 62311.161 | E10: 33.628153 | F10: -1.3754037 | H10: 38133.63 | I10: 31.698238 | J10: -0.3899205 | L10: 30278.388 | M10: 30.044223 | N10: -1.2564829 | P10: 30053.544 | Q10: 33.532352 | R10: -1.4253314
A11: 34731 | B11: Tyne and Wear | C11: E11000007 | D11: 76246.97 | E11: 33.864829 | F11: 0.66673691 | H11: 44972.006 | I11: 33.288555 | J11: 1.8990937 | L11: 36499.592 | M11: 31.808081 | N11: 1.6095305 | P11: 31542.58 | Q11: 35.027733 | R11: 0.58131185
A12: 34731 | B12: Merseyside | C12: E11000002 | D12: 75070.66 | E12: 35.14648 | F12: -1.70871 | H12: 46003.379 | I12: 33.698476 | J12: -0.33986214 | L12: 31199.019 | M12: 32.214 | N12: -1.8406306 | P12: 32131.953 | Q12: 36.239706 | R12: -0.37981824
A13: 34731 | B13: Greater Manchester | C13: E11000001 | D13: 75229.49 | E13: 32.827842 | F13: -0.46020085 | H13: 44804.43 | I13: 30.33789 | J13: 0.57403154 | L13: 32758.61 | M13: 30.163999 | N13: 0.33113531 | P13: 34588.609 | Q13: 31.598379 | R13: -0.45475461
A14: 34759 | B14: Greater Manchester | C14: E11000001 | D14: 75382.788 | E14: 32.894737 | F14: 0.20377339 | H14: 44932.825 | I14: 30.424828 | J14: 0.28656675 | L14: 32925.605 | M14: 30.317766 | N14: 0.5097723 | P14: 34723.624 | Q14: 31.721722 | R14: 0.39034382
A15: 34759 | B15: South Yorkshire | C15: E11000003 | D15: 62502.325 | E15: 33.731321 | F15: 0.30678999 | H15: 38337.345 | I15: 31.867574 | J15: 0.53421504 | L15: 30447.304 | M15: 30.211833 | N15: 0.55787681 | P15: 30079.543 | Q15: 33.561361 | R15: 0.086509491
A16: 34759 | B16: Tyne and Wear | C16: E11000007 | D16: 76358.594 | E16: 33.914407 | F16: 0.14639803 | H16: 45001.677 | I16: 33.310518 | J16: 0.065977815 | L16: 36642.671 | M16: 31.932768 | N16: 0.39199937 | P16: 31441.917 | Q16: 34.915948 | R16: -0.31913286
A17: 34759 | B17: West Midlands | C17: E11000005 | D17: 83383.975 | E17: 33.199606 | F17: 0.19678598 | H17: 48018.635 | I17: 31.997916 | J17: 0.55466454 | L17: 37438.534 | M17: 30.304333 | N17: 0.76787344 | P17: 35279.75 | Q17: 34.624717 | R17: 0.51546837
A18: 34759 | B18: West Yorkshire | C18: E11000006 | D18: 77797.195 | E18: 34.615655 | F18: 0.18810466 | H18: 45668.819 | I18: 33.344376 | J18: 0.52346447 | L18: 35663.408 | M18: 33.057967 | N18: 0.63620042 | P18: 35101.566 | Q18: 35.800605 | R18: 0.54687168
A19: 34759 | B19: Merseyside | C19: E11000002 | D19: 75582.608 | E19: 35.386163 | F19: 0.68195461 | H19: 46375.01 | I19: 33.970704 | J19: 0.80783406 | L19: 31605.328 | M19: 32.633527 | N19: 1.3023132 | P19: 32298.887 | Q19: 36.427981 | R19: 0.51952692
... A73: 35034 | B73: West Midlands | C73: E11000005 | D73: 82800.321 | E73: 32.967222 | F73: -0.80189986 | H73: 47833.409 | I73: 31.874488 | J73: -0.45559159 | L73: 36964.263 | M73: 29.920437 | N73: -0.54978526 | P73: 34924.882 | Q73: 34.276438 | R73: -0.3412056
A74: 35065 | B74: Merseyside | C74: E11000002 | D74: 75528.019 | E74: 35.360605 | F74: 0.15349098 | G74: -1.1098821 | H74: 46129.322 | I74: 33.790732 | J74: -0.2636394 | K74: -0.06702359 | L74: 30941.899 | M74: 31.948515 | N74: -0.36839429 | O74: -2.6495897 | P74: 32198.247 | Q74: 36.314476 | R74: -0.60368613 | S74: -0.17428243
A75: 35065 | B75: Tyne and Wear | C75: E11000007 | D75: 76493.339 | E75: 33.974254 | F75: -0.46688508 | G75: 0.99201168 | H75: 44664.255 | I75: 33.060756 | J75: -0.71027833 | K75: 1.2017816 | L75: 35968.184 | M75: 31.344978 | N75: -0.78425457 | O75: 0.13016828 | P75: 30808.292 | Q75: 34.212313 | R75: -0.65472942 | S75: -1.7601481
A76: 35065 | B76: West Yorkshire | C76: E11000006 | D76: 76780.099 | E76: 34.163102 | F76: -0.53741565 | G76: -1.7066699 | H76: 44804.604 | I76: 32.713383 | J76: -0.66839295 | K76: -0.68390551 | L76: 34487.018 | M76: 31.96752 | N76: -0.53831807 | O76: -2.6207313 | P76: 34172.351 | Q76: 34.852885 | R76: -0.98203826 | S76: -1.6473317
A77: 35065 | B77: South Yorkshire | C77: E11000003 | D77: 63554.478 | E77: 34.299148 | F77: -0.54856322 | G77: 0.59248901 | H77: 38619.411 | I77: 32.102039 | J77: -0.92004101 | K77: 0.87900461 | L77: 30197.945 | M77: 29.964402 | N77: -1.2113584 | O77: -1.5188237 | P77: 29918.526 | Q77: 33.381706 | R77: -1.6011226 | S77: -1.8681853
A78: 35065 | B78: West Midlands | C78: E11000005 | D78: 82090.583 | E78: 32.684638 | F78: -0.85716819 | G78: -1.2700664 | H78: 47220.538 | I78: 31.466093 | J78: -1.2812602 | K78: 0.48905977 | L78: 36345.869 | M78: 29.419884 | N78: -1.6729489 | O78: -0.85990118 | P78: 34292.616 | Q78: 33.655912 | R78: -1.8103586 | S78: -1.2973082
A79: 35065 | B79: Greater Manchester | C79: E11000001 | D79: 74509.113 | E79: 32.513491 | F79: 0.014644298 | G79: -1.413368 | H79: 44029.017 | I79: 29.812844 | J79: -0.28470515 | K79: -1.1665656 | L79: 31694.42 | M79: 29.184096 | N79: -0.17668623 | O79: -2.9282039 | P79: 33689.336 | Q79: 30.776849 | R79: -0.35890863 | S79: -3.0428436
A80: 35096 | B80: Greater Manchester | C80: E11000001 | D80: 74346.284 | E80: 32.442438 | F80: -0.2185344 | G80: -1.1740156 | H80: 43941.599 | I80: 29.753651 | J80: -0.19854591 | K80: -1.9257723 | L80: 31585.905 | M80: 29.084176 | N80: -0.342379 | O80: -3.5798386 | P80: 33393.154 | Q80: 30.506272 | R80: -0.87915645 | S80: -3.4562114
A81: 35096 | B81: West Midlands | C81: E11000005 | D81: 82599.919 | E81: 32.887431 | F81: 0.62045528 | G81: -0.74536097 | H81: 47489.785 | I81: 31.645509 | J81: 0.5701897 | K81: -0.55278765 | L81: 36497.668 | M81: 29.542756 | N81: 0.41764917 | O81: -1.764521 | P81: 34288.495 | Q81: 33.651868 | R81: -0.012016548 | S81: -2.308712
A82: 35096 | B82: Tyne and Wear | C82: E11000007 | D82: 75371.69 | E82: 33.476077 | F82: -1.4663365 | G82: -1.1479541 | H82: 44135.59 | I82: 32.669435 | J82: -1.1836425 | K82: -1.8598589 | L82: 35537.83 | M82: 30.969939 | N82: -1.1964875 | O82: -2.6349962 | P82: 30391.441 | Q82: 33.749404 | R82: -1.3530464 | S82: -3.6494759
A83: 35096 | B83: West Yorkshire | C83: E11000006 | D83: 76522.852 | E83: 34.04864 | F83: -0.33504416 | G83: -1.4530081 | H83: 44792.649 | I83: 32.704654 | J83: -0.026682789 | K83: -1.4051088 | L83: 34495.021 | M83: 31.974938 | N83: 0.023204733 | O83: -2.6607941 | P83: 34039.104 | Q83: 34.716984 | R83: -0.38992563 | S83: -2.4965048
A84: 35096 | B84: South Yorkshire | C84: E11000003 | D84: 62922.811 | E84: 33.958249 | F84: -0.99389918 | G84: 0.98160583 | H84: 38293.142 | I84: 31.830831 | J84: -0.84483158 | K84: 0.41829845 | L84: 29921.699 | M84: 29.690292 | N84: -0.91478315 | O84: -1.1780317 | P84: 29543.506 | Q84: 32.963275 | R84: -1.2534715 | S84: -1.6970975
A85: 35096 | B85: Merseyside | C85: E11000002 | D85: 75732.104 | E85: 35.456154 | F85: 0.27021136 | G85: 0.88109559 | H85: 46265.278 | I85: 33.890323 | J85: 0.29472861 | K85: 0.56930447 | L85: 31147.46 | M85: 32.160763 | N85: 0.66434272 | O85: -0.16526052 | P85: 32044.576 | Q85: 36.141159 | R85: -0.47726517 | S85: -0.27193042
... A2017: 44896 | B2017: Tyne and Wear | C2017: E11000007 | D2017: 335451.25 | E2017: 148.98956 | F2017: 0.77896892 | G2017: 13.60782 | H2017: 190806.39 | I2017: 141.23607 | J2017: 0.44354194 | K2017: 11.999197 | L2017: 158829.02 | M2017: 138.41378 | N2017: 0.2832319 | O2017: 11.994368 | P2017: 111302.36 | Q2017: 123.6002 | R2017: 0.93705647 | S2017: 9.5818752

Sheet GDP
A1: Year | B1: Season | C1: Type | D1: Figure
A2: 2000 | B2: Spring | C2: Food | D2: 14213
A3: 2000 | B3: Summer | C3: Food | D3: 14055
A4: 2000 | B4: Fall | C4: Food | D4: 14340
A5: 2000 | B5: Winter | C5: Food | D5: 14388
A6: 2001 | B6: Spring | C6: Food | D6: 14495
A7: 2001 | B7: Summer | C7: Food | D7: 14469
A8: 2001 | B8: Fall | C8: Food | D8: 14894
A9: 2001 | B9: Winter | C9: Food | D9: 15239
A10: 2002 | B10: Spring | C10: Food | D10: 14748
A11: 2002 | B11: Summer | C11: Food | D11: 14732
A12: 2002 | B12: Fall | C12: Food | D12: 15117
A13: 2002 | B13: Winter | C13: Food | D13: 15732
... A90: 2022 | B90: Spring | C90: Food | D90: 30338
A91: 2022 | B91: Summer | C91: Food | D91: 31182 | F91: 10
A92: 2022 | B92: Fall | C92: Food | D92: 32333
A93: 2000 | B93: Spring | C93: Alcohol | D93: 8121
A94: 2000 | B94: Summer | C94: Alcohol | D94: 8163
A95: 2000 | B95: Fall | C95: Alcohol | D95: 8189
A96: 2000 | B96: Winter | C96: Alcohol | D96: 8165
A97: 2001 | B97: Spring | C97: Alcohol | D97: 8195
A98: 2001 | B98: Summer | C98: Alcohol | D98: 8221
A99: 2001 | B99: Fall | C99: Alcohol | D99: 8187
A100: 2001 | B100: Winter | C100: Alcohol | D100: 8120
A101: 2002 | B101: Spring | C101: Alcohol | D101: 8111
A102: 2002 | B102: Summer | C102: Alcohol | D102: 8104
A103: 2002 | B103: Fall | C103: Alcohol | D103: 8115
... A1093: 2022 | B1093: Fall | C1093: Miscellaneous | D1093: 43919

Sheet NPER
A1: NPER Example 1 - Mortgage
A3: Annual interest rate | B3: 0.2
A4: Interest rate per period | B4: =B3/12 -> 0.016666667
A5: Payment made in each period | B5: -4000 | C5: Money you are paying out is negative
A6: Present value (worth now) | B6: 200000
A7: Future value (worth at end) | B7: 0
A8: Payments are made at beginning or end of period | B8: 0 | C8: 0 or omitted = end; 1 = beginning
A10: Number of periods | B10: =NPER(B4,B5,B6,B7,B8) -> 108.39898
A12: NPER Example 2 - Investment
A14: Annual interest rate | B14: 0.08
A15: Interest rate per period | B15: =B14/12 -> 0.0066666667
A16: Payment made in each period | B16: -40
A17: Present value (worth now) | B17: 0
A18: Future value (worth at end) | B18: 100000
A19: Payments are made at beginning or end of period | B19: 0
A21: Number of periods | B21: =NPER(B15,B16,B17,B18,B19) -> 432.18619
A23: Calculate only if at least $100 investment, and interest rate is at least 5% | B23: =IF(AND(B14>=5%,B16<=-100),NPER(B15,B16,B17,B18,B19),"Speak to your advisor") -> Speak to your advisor

Sheet PMT
A1: NPER Example 1 - Mortgage
A3: Annual interest rate | B3: 0.1
A4: Interest rate per period | B4: =B3/12 -> 0.0083333333
A5: Number of periods | B5: 150
A6: Present value (worth now) | B6: 200000
A7: Future value (worth at end) | B7: 0
A8: Payments are made at beginning or end of period | B8: 0 | C8: 0 or omitted = end; 1 = beginning
A10: Payment needed | B10: =PMT(B4,B5,B6,B7,B8) -> -2340.7997
A12: NPER Example 2 - Investment
A14: Annual interest rate | B14: 0.08
A15: Interest rate per period | B15: =B14/12 -> 0.0066666667
A16: Number of periods | B16: 180
A17: Present value (worth now) | B17: 0
A18: Future value (worth at end) | B18: 100000
A19: Payments are made at beginning or end of period | B19: 0
A21: Investment needed | B21: =PMT(B15,B16,B17,B18,B19) -> -288.98542

Sheet Goal Seek
A1: Goal Seek - Example 1
A3: Sales Tax Rate | B3: 0.07
A4: Price before Sales Tax | B4: 200
A5: Sales Tax Cost | B5: =B4*B3 -> 14
A6: Total | B6: =SUM(B4:B5) -> 214
A8: Goal Seek - Example 2
A10: Input value | B10: -4
A11: Value squared | B11: =B10*B10 -> 16
A13: Goal Seek - Example 3
B15: Value | C15: Value squared
A16: Initial value | B16: 3 | C16: =B16*B16 -> 9
A17: Next value | B17: =B16+1 -> 4 | C17: =B17*B17 -> 16
A18: Next value | B18: =B17+1 -> 5 | C18: =B18*B18 -> 25
A19: Next value | B19: =B18+1 -> 6 | C19: =B19*B19 -> 36
A20: Next value | B20: =B19+1 -> 7 | C20: =B20*B20 -> 49
A21: Next value | B21: =B20+1 -> 8 | C21: =B21*B21 -> 64
A22: Next value | B22: =B21+1 -> 9 | C22: =B22*B22 -> 81
A23: Grand Total | C23: =SUM(C16:C22) -> 280

Sheet Workday
G1: Calendar | P1: Holidays
H3: Mon | I3: Tues | J3: Wed | K3: Thurs | L3: Fri | M3: Sat | N3: Sun | P3: 45649
A4: Date From | B4: 45638 | N4: 1 | P4: 45650
A5: Days | B5: -10 | G5: December 2024 | H5: 2 | I5: 3 | J5: 4 | K5: 5 | L5: 6 | M5: 7 | N5: 8 | P5: 45651
B6: =WORKDAY(B4,B5,P3:P16) -> 45624 | H6: =H5+7 -> 9 | I6: =I5+7 -> 10 | J6: =J5+7 -> 11 | K6: =K5+7 -> 12 | L6: =L5+7 -> 13 | M6: =M5+7 -> 14 | N6: =N5+7 -> 15 | P6: 45652
B7: =WORKDAY.INTL(B4,B5,"0000111",P3:P16) -> 45622 | H7: =H6+7 -> 16 | I7: =I6+7 -> 17 | J7: =J6+7 -> 18 | K7: =K6+7 -> 19 | L7: =L6+7 -> 20 | M7: =M6+7 -> 21 | N7: =N6+7 -> 22 | P7: 45653
H8: =H7+7 -> 23 | I8: =I7+7 -> 24 | J8: =J7+7 -> 25 | K8: =K7+7 -> 26 | L8: =L7+7 -> 27 | M8: =M7+7 -> 28 | N8: =N7+7 -> 29 | P8: 45654
H9: =H8+7 -> 30 | I9: =I8+7 -> 31 | P9: 45655
P10: 45656
G11: January 2025 | J11: 1 | K11: 2 | L11: 3 | M11: 4 | N11: 5 | P11: 45657
H12: 6 | I12: 7 | J12: =J11+7 -> 8 | K12: =K11+7 -> 9 | L12: =L11+7 -> 10 | M12: =M11+7 -> 11 | N12: =N11+7 -> 12 | P12: 45658
H13: =H12+7 -> 13 | I13: =I12+7 -> 14 | J13: =J12+7 -> 15 | K13: =K12+7 -> 16 | L13: =L12+7 -> 17 | M13: =M12+7 -> 18 | N13: =N12+7 -> 19 | P13: 45659
H14: =H13+7 -> 20 | I14: =I13+7 -> 21 | J14: =J13+7 -> 22 | K14: =K13+7 -> 23 | L14: =L13+7 -> 24 | M14: =M13+7 -> 25 | N14: =N13+7 -> 26 | P14: 45660
H15: =H14+7 -> 27 | I15: =I14+7 -> 28 | J15: =J14+7 -> 29 | K15: =K14+7 -> 30 | L15: =L14+7 -> 31 | P15: 45661
P16: 45662

Sheet Consolidate1
A1: Month | B1: Cost
A2: January | B2: 10
A3: February | B3: 20
A4: March | B4: 30
A5: April | B5: 40
A6: May | B6: 50
A7: June | B7: 60
A8: July | B8: 70
A9: August | B9: 80
A10: September | B10: 90
A11: October | B11: 100
A12: November | B12: 110
A13: December | B13: 120

Sheet Consolidate2
A1: Month | B1: Cost
A2: January | B2: 130
A3: February | B3: 140
A4: March | B4: 150
A5: April | B5: 160
A6: May | B6: 170
A7: June | B7: 180
A8: July | B8: 190
A9: August | B9: 200
A10: September | B10: 210
A11: October | B11: 220
A12: November | B12: 230
A13: December | B13: 240

Sheet Consolidate3
A1: Month | B1: Cost
A2: January | B2: {=_xlfn.RANDARRAY(12,1,130,400,TRUE)} -> 376
A3: February | B3: 292
A4: March | B4: 153
A5: April | B5: 357
A6: May | B6: 130
A7: June | B7: 385
A8: July | B8: 226
A9: August | B9: 297
A10: September | B10: 146
A11: October | B11: 201
A12: November | B12: 270
A13: December | B13: 286

Sheet Categories
A1: Path | B1: First row | C1: Last row | D1: Category | G1: First song | H1: Last song
A2: \10 Romantic works\ | B2: =MATCH(A2,[1]CDs!$D$3:$D$861,0) -> 2 | C2: =MATCH(A2,[1]CDs!D2:D860,1) -> 17 | D2: Sampler | E2: {=INDEX(CDs!$B$3:$B$861,B2,1)} -> 02 Symphony 3 in F Mayor 1est. Mov.wma | F2: {=INDEX(CDs!$B$3:$B$861,C2,1)} -> 01 Deposuit potentes.wma | G2: =_xlfn.XLOOKUP($A2,[1]CDs!$D$3:$D$861,[1]CDs!$B$3:$B$861,"Not matched",0,1) -> 02 Symphony 3 in F Mayor 1est. Mov.wma | H2: =_xlfn.XLOOKUP($A2,[1]CDs!$D$3:$D$861,[1]CDs!$B$3:$B$861,"Not matched",0,-1) -> 17 On a Overgrown Path.wma | I2: 1000000 | R2: =_xlfn.XLOOKUP($A2,CDs!$D$3:$D$861,CDs!$B$3:$B$861) -> 02 Symphony 3 in F Mayor 1est. Mov.wma
A3: \1000 Years Of Sacred Music Disc 4\ | B3: =MATCH(A3,[1]CDs!$D$3:$D$861,0) -> 17 | C3: =MATCH(A3,[1]CDs!D3:D861,1) -> 36 | D3: Sampler | E3: {=INDEX(CDs!$B$3:$B$861,B3,1)} -> 01 Deposuit potentes.wma | F3: {=INDEX(CDs!$B$3:$B$861,C3,1)} -> 20 Funeral March.wma | G3: =_xlfn.XLOOKUP(A3,[1]CDs!D4:D862,[1]CDs!B4:B862,"Not matched") -> 01 Deposuit potentes.wma | H3: =_xlfn.XLOOKUP($A3,[1]CDs!$D$3:$D$861,[1]CDs!$B$3:$B$861,"Not matched",0,-1) -> 20 Funeral March.wma | I3: =I2/2 -> 500000 | R3: =_xlfn.XLOOKUP($A3,CDs!$D$3:$D$861,CDs!$B$3:$B$861) -> 01 Deposuit potentes.wma
A4: \1991 Collection\ | B4: =MATCH(A4,[1]CDs!$D$3:$D$861,0) -> 37 | C4: =MATCH(A4,[1]CDs!D4:D862,1) -> 48 | D4: Sampler | E4: {=INDEX(CDs!$B$3:$B$861,B4,1)} -> 01 Lamento d' Ariannna.wma | F4: {=INDEX(CDs!$B$3:$B$861,C4,1)} -> 12 Asturias.wma | G4: =_xlfn.XLOOKUP(A4,[1]CDs!D5:D863,[1]CDs!B5:B863,"Not matched") -> 01 Lamento d' Ariannna.wma | H4: =_xlfn.XLOOKUP($A4,[1]CDs!$D$3:$D$861,[1]CDs!$B$3:$B$861,"Not matched",0,-1) -> 13 From Bohemia's Meadows and Groves.wma | I4: =I3/2 -> 250000 | R4: =_xlfn.XLOOKUP($A4,CDs!$D$3:$D$861,CDs!$B$3:$B$861) -> 01 Lamento d' Ariannna.wma
A5: \37257\ | B5: =MATCH(A5,[1]CDs!$D$3:$D$861,0) -> 50 | C5: =MATCH(A5,[1]CDs!D5:D863,1) -> 64 | D5: Sampler | E5: {=INDEX(CDs!$B$3:$B$861,B5,1)} -> 01 Piano Sonata in B Flat, K333 - Allegretto Grazioso.wma | F5: {=INDEX(CDs!$B$3:$B$861,C5,1)} -> 15 Competition 2.wma | G5: =_xlfn.XLOOKUP(A5,[1]CDs!D6:D864,[1]CDs!B6:B864,"Not matched") -> 01 Piano Sonata in B Flat, K333 - Allegretto Grazioso.wma | H5: =_xlfn.XLOOKUP($A5,[1]CDs!$D$3:$D$861,[1]CDs!$B$3:$B$861,"Not matched",0,-1) -> 17 Competition 4.wma | I5: =I4/2 -> 125000 | R5: =_xlfn.XLOOKUP($A5,CDs!$D$3:$D$861,CDs!$B$3:$B$861) -> 01 Piano Sonata in B Flat, K333 - Allegretto Grazioso.wma
A6: \3D classics\a | B6: =MATCH(A6,[1]CDs!$D$3:$D$861,0) -> #N/A | C6: =MATCH(A6,[1]CDs!D6:D864,1) -> 71 | D6: Sampler | E6: {=INDEX(CDs!$B$3:$B$861,B6,1)} -> #N/A | F6: {=INDEX(CDs!$B$3:$B$861,C6,1)} -> 05 From Holberg's Time, Rigaudon.wma | G6: =_xlfn.XLOOKUP(A6,[1]CDs!D7:D865,[1]CDs!B7:B865,"Not matched") -> Not matched | H6: =_xlfn.XLOOKUP($A6,[1]CDs!$D$3:$D$861,[1]CDs!$B$3:$B$861,"Not matched",0,-1) -> Not matched | I6: =I5/2 -> 62500 | R6: =_xlfn.XLOOKUP($A6,CDs!$D$3:$D$861,CDs!$B$3:$B$861) -> #N/A
A7: \40Th Anniversary\ | B7: =MATCH(A7,[1]CDs!$D$3:$D$861,0) -> #N/A | C7: =MATCH(A7,[1]CDs!D7:D865,1) -> 70 | D7: Sampler | E7: {=INDEX(CDs!$B$3:$B$861,B7,1)} -> #N/A | F7: {=INDEX(CDs!$B$3:$B$861,C7,1)} -> 04 From Holberg's Time, Air.wma | G7: =_xlfn.XLOOKUP(A7,[1]CDs!D8:D866,[1]CDs!B8:B866,"Not matched") -> Not matched | H7: =_xlfn.XLOOKUP($A7,[1]CDs!$D$3:$D$861,[1]CDs!$B$3:$B$861,"Not matched",0,-1) -> Not matched | I7: =I6/2 -> 31250 | R7: =_xlfn.XLOOKUP($A7,CDs!$D$3:$D$861,CDs!$B$3:$B$861) -> #N/A
A8: \A Decade Of Excellence\ | B8: =MATCH(A8,[1]CDs!$D$3:$D$861,0) -> 75 | C8: =MATCH(A8,[1]CDs!D8:D866,1) -> 90 | D8: Sampler | E8: {=INDEX(CDs!$B$3:$B$861,B8,1)} -> 01 Handel- Arias for Durastanti.wma | F8: {=INDEX(CDs!$B$3:$B$861,C8,1)} -> 16 La Spagna.wma | G8: =_xlfn.XLOOKUP(A8,[1]CDs!D9:D867,[1]CDs!B9:B867,"Not matched") -> 01 Handel- Arias for Durastanti.wma | H8: =_xlfn.XLOOKUP($A8,[1]CDs!$D$3:$D$861,[1]CDs!$B$3:$B$861,"Not matched",0,-1) -> 21 WALTON.wma | I8: =I7/2 -> 15625 | R8: =_xlfn.XLOOKUP($A8,CDs!$D$3:$D$861,CDs!$B$3:$B$861) -> 01 Handel- Arias for Durastanti.wma
A9: \a mad world, my masters\ | B9: =MATCH(A9,[1]CDs!$D$3:$D$861,0) -> 96 | C9: =MATCH(A9,[1]CDs!D9:D867,1) -> 90 | D9: Audiobook | E9: {=INDEX(CDs!$B$3:$B$861,B9,1)} -> a mad world, my masters.m4b | F9: {=INDEX(CDs!$B$3:$B$861,C9,1)} -> 16 La Spagna.wma | G9: =_xlfn.XLOOKUP(A9,[1]CDs!D10:D868,[1]CDs!B10:B868,"Not matched") -> a mad world, my masters.m4b | H9: =_xlfn.XLOOKUP($A9,[1]CDs!$D$3:$D$861,[1]CDs!$B$3:$B$861,"Not matched",0,-1) -> a mad world, my masters.m4b | I9: =I8/2 -> 7812.5 | R9: =_xlfn.XLOOKUP($A9,CDs!$D$3:$D$861,CDs!$B$3:$B$861) -> a mad world, my masters.m4b
A10: \a musical offering\ | B10: =MATCH(A10,[1]CDs!$D$3:$D$861,0) -> 97 | C10: =MATCH(A10,[1]CDs!D10:D868,1) -> 103 | D10: Sampler | E10: {=INDEX(CDs!$B$3:$B$861,B10,1)} -> 01 Blumenfest Polka.wma | F10: {=INDEX(CDs!$B$3:$B$861,C10,1)} -> 08 The Padstow Lifeboat.wma | G10: =_xlfn.XLOOKUP(A10,[1]CDs!D11:D869,[1]CDs!B11:B869,"Not matched") -> 01 Blumenfest Polka.wma | H10: =_xlfn.XLOOKUP($A10,[1]CDs!$D$3:$D$861,[1]CDs!$B$3:$B$861,"Not matched",0,-1) -> 16 turandot-puccini.wma | I10: =I9/2 -> 3906.25 | R10: =_xlfn.XLOOKUP($A10,CDs!$D$3:$D$861,CDs!$B$3:$B$861) -> 01 Blumenfest Polka.wma
A11: \A New Statement in Classical Music\ | B11: =MATCH(A11,[1]CDs!$D$3:$D$861,0) -> 111 | C11: =MATCH(A11,[1]CDs!D11:D869,1) -> 111 | D11: Sampler | E11: {=INDEX(CDs!$B$3:$B$861,B11,1)} -> 04 Symphony No. 5 in C minor ('Fate') Op. 67- First Movement.wma | F11: {=INDEX(CDs!$B$3:$B$861,C11,1)} -> 04 Symphony No. 5 in C minor ('Fate') Op. 67- First Movement.wma | G11: =_xlfn.XLOOKUP(A11,[1]CDs!D12:D870,[1]CDs!B12:B870,"Not matched") -> 04 Symphony No. 5 in C minor ('Fate') Op. 67- First Movement.wma | H11: =_xlfn.XLOOKUP($A11,[1]CDs!$D$3:$D$861,[1]CDs!$B$3:$B$861,"Not matched",0,-1) -> 13 Messiah, oratorio, HWV 56- Hallelujah.wma | I11: =I10/2 -> 1953.125 | R11: =_xlfn.XLOOKUP($A11,CDs!$D$3:$D$861,CDs!$B$3:$B$861) -> 04 Symphony No. 5 in C minor ('Fate') Op. 67- First Movement.wma
A12: \A Night At The Opera II\ | B12: =MATCH(A12,[1]CDs!$D$3:$D$861,0) -> 120 | C12: =MATCH(A12,[1]CDs!D12:D870,1) -> 143 | D12: Opera | E12: {=INDEX(CDs!$B$3:$B$861,B12,1)} -> 01 Eugene Onegin- Waltz.wma | F12: {=INDEX(CDs!$B$3:$B$861,C12,1)} -> 12 La Gioconda Cielo E Mar.wma | G12: =_xlfn.XLOOKUP(A12,[1]CDs!D13:D871,[1]CDs!B13:B871,"Not matched") -> 01 Eugene Onegin- Waltz.wma | H12: =_xlfn.XLOOKUP($A12,[1]CDs!$D$3:$D$861,[1]CDs!$B$3:$B$861,"Not matched",0,-1) -> 18 Don Giovanni.wma | I12: =I11/2 -> 976.5625 | R12: =_xlfn.XLOOKUP($A12,CDs!$D$3:$D$861,CDs!$B$3:$B$861) -> 01 Eugene Onegin- Waltz.wma
A13: \Adagio Serene Classical Music for a Peaceful Mind Disc 1\ | B13: =MATCH(A13,[1]CDs!$D$3:$D$861,0) -> 153 | C13: =MATCH(A13,[1]CDs!D13:D871,1) -> 146 | D13: Sampler | E13: {=INDEX(CDs!$B$3:$B$861,B13,1)} -> 01 Adagio, From Clarinet Concerto.wma | F13: {=INDEX(CDs!$B$3:$B$861,C13,1)} -> 14 Lady Macbeth of Mtsensk.wma | G13: =_xlfn.XLOOKUP(A13,[1]CDs!D14:D872,[1]CDs!B14:B872,"Not matched") -> 01 Adagio, From Clarinet Concerto.wma | H13: =_xlfn.XLOOKUP($A13,[1]CDs!$D$3:$D$861,[1]CDs!$B$3:$B$861,"Not matched",0,-1) -> 04 Andante, From Piano Concerto No. 21 'Elvira Madigan'.wma | I13: =I12/2 -> 488.28125 | R13: =_xlfn.XLOOKUP($A13,CDs!$D$3:$D$861,CDs!$B$3:$B$861) -> 01 Adagio, From Clarinet Concerto.wma
